<?xml version="1.0" encoding="utf-8"?>
<!-- This URDF was automatically created by SolidWorks to URDF Exporter! Originally created by Stephen Brawner (brawner@gmail.com) 
     Commit Version: 1.6.0-4-g7f85cfe  Build Version: 1.6.7995.38578
     For more information, please see http://wiki.ros.org/sw_urdf_exporter -->
<robot
  name="00-disr-assy_asm">
  <link
    name="base_link">
    <inertial>
      <origin
        xyz="-0.029112 -4.9618E-05 0.037384"
        rpy="0 0 0" />
      <mass
        value="0.15758" />
      <inertia
        ixx="0.00020705"
        ixy="1.1867E-06"
        ixz="2.8584E-06"
        iyy="0.00027968"
        iyz="2.2254E-06"
        izz="0.00038174" />
    </inertial>
    <visual>
      <origin
        xyz="0 0 0"
        rpy="0 0 0" />
      <geometry>
        <mesh
          filename="../meshes/base_link.STL" />
      </geometry>
      <material
        name="">
        <color
          rgba="1 1 1 1" />
      </material>
    </visual>
    <collision>
      <origin
        xyz="0 0 0"
        rpy="0 0 0" />
      <geometry>
        <mesh
          filename="../meshes/base_link.STL" />
      </geometry>
    </collision>
  </link>
  <link
    name="link1">
    <inertial>
      <origin
        xyz="3.6472E-06 -0.0049778 -0.0097341"
        rpy="0 0 0" />
      <mass
        value="0.10631" />
      <inertia
        ixx="4.2478E-05"
        ixy="-1.0356E-09"
        ixz="7.3521E-09"
        iyy="5.9445E-05"
        iyz="5.0371E-06"
        izz="5.3189E-05" />
    </inertial>
    <visual>
      <origin
        xyz="0 0 0"
        rpy="0 0 0" />
      <geometry>
        <mesh
          filename="../meshes/link1.STL" />
      </geometry>
      <material
        name="">
        <color
          rgba="1 1 1 1" />
      </material>
    </visual>
    <collision>
      <origin
        xyz="0 0 0"
        rpy="0 0 0" />
      <geometry>
        <mesh
          filename="../meshes/link1.STL" />
      </geometry>
    </collision>
  </link>
  <joint
    name="joint1"
    type="revolute">
    <origin
      xyz="0 2.4795E-05 0.117"
      rpy="0 0 0" />
    <parent
      link="base_link" />
    <child
      link="link1" />
    <axis
      xyz="0 0 1" />
    <limit
      lower="-10"
      upper="10"
      effort="100"
      velocity="110" />
  </joint>
  <link
    name="link2">
    <inertial>
      <origin
        xyz="0.16303 0.01241 0.0045681"
        rpy="0 0 0" />
      <mass
        value="0.2275" />
      <inertia
        ixx="0.00011733"
        ixy="-7.1761E-05"
        ixz="1.7806E-05"
        iyy="0.0014114"
        iyz="2.8994E-06"
        izz="0.0014746" />
    </inertial>
    <visual>
      <origin
        xyz="0 0 0"
        rpy="0 0 0" />
      <geometry>
        <mesh
          filename="../meshes/link2.STL" />
      </geometry>
      <material
        name="">
        <color
          rgba="1 1 1 1" />
      </material>
    </visual>
    <collision>
      <origin
        xyz="0 0 0"
        rpy="0 0 0" />
      <geometry>
        <mesh
          filename="../meshes/link2.STL" />
      </geometry>
    </collision>
  </link>
  <joint
    name="joint2"
    type="revolute">
    <origin
      xyz="0 0 0"
      rpy="-1.5708 -0.38673 3.1416" />
    <parent
      link="link1" />
    <child
      link="link2" />
    <axis
      xyz="0 0 1" />
    <limit
      lower="-10"
      upper="10"
      effort="100"
      velocity="110" />
  </joint>
  <link
    name="link3">
    <inertial>
      <origin
        xyz="0.00031865 -0.16931 -0.00094181"
        rpy="0 0 0" />
      <mass
        value="0.14117" />
      <inertia
        ixx="0.00041644"
        ixy="-4.7139E-07"
        ixz="-2.1254E-09"
        iyy="7.1543E-05"
        iyz="3.7878E-06"
        izz="0.00042197" />
    </inertial>
    <visual>
      <origin
        xyz="0 0 0"
        rpy="0 0 0" />
      <geometry>
        <mesh
          filename="../meshes/link3.STL" />
      </geometry>
      <material
        name="">
        <color
          rgba="1 1 1 1" />
      </material>
    </visual>
    <collision>
      <origin
        xyz="0 0 0"
        rpy="0 0 0" />
      <geometry>
        <mesh
          filename="../meshes/link3.STL" />
      </geometry>
    </collision>
  </link>
  <joint
    name="joint3"
    type="revolute">
    <origin
      xyz="0.27009 0 0"
      rpy="0 0 -1.1841" />
    <parent
      link="link2" />
    <child
      link="link3" />
    <axis
      xyz="0 0 1" />
    <limit
      lower="-10"
      upper="10"
      effort="100"
      velocity="110" />
  </joint>
  <link
    name="link4">
    <inertial>
      <origin
        xyz="-0.0051834 0.00019368 -0.0082929"
        rpy="0 0 0" />
      <mass
        value="0.057816" />
      <inertia
        ixx="3.2684E-05"
        ixy="-2.4663E-09"
        ixz="5.0516E-06"
        iyy="2.5781E-05"
        iyz="-1.1525E-09"
        izz="2.1405E-05" />
    </inertial>
    <visual>
      <origin
        xyz="0 0 0"
        rpy="0 0 0" />
      <geometry>
        <mesh
          filename="../meshes/link4.STL" />
      </geometry>
      <material
        name="">
        <color
          rgba="1 1 1 1" />
      </material>
    </visual>
    <collision>
      <origin
        xyz="0 0 0"
        rpy="0 0 0" />
      <geometry>
        <mesh
          filename="../meshes/link4.STL" />
      </geometry>
    </collision>
  </link>
  <joint
    name="joint4"
    type="revolute">
    <origin
      xyz="0.0029191 -0.30866 0"
      rpy="1.5708 0 0" />
    <parent
      link="link3" />
    <child
      link="link4" />
    <axis
      xyz="0 0 1" />
    <limit
      lower="-10"
      upper="10"
      effort="100"
      velocity="110" />
  </joint>
  <link
    name="link5">
    <inertial>
      <origin
        xyz="-0.039982 -0.00063731 -0.0029755"
        rpy="0 0 0" />
      <mass
        value="0.071803" />
      <inertia
        ixx="3.5881E-05"
        ixy="-1.0415E-07"
        ixz="-6.6076E-06"
        iyy="3.823E-05"
        iyz="1.4119E-08"
        izz="3.7202E-05" />
    </inertial>
    <visual>
      <origin
        xyz="0 0 0"
        rpy="0 0 0" />
      <geometry>
        <mesh
          filename="../meshes/link5.STL" />
      </geometry>
      <material
        name="">
        <color
          rgba="1 1 1 1" />
      </material>
    </visual>
    <collision>
      <origin
        xyz="0 0 0"
        rpy="0 0 0" />
      <geometry>
        <mesh
          filename="../meshes/link5.STL" />
      </geometry>
    </collision>
  </link>
  <joint
    name="joint5"
    type="revolute">
    <origin
      xyz="0 0 0"
      rpy="0 1.5708 0" />
    <parent
      link="link4" />
    <child
      link="link5" />
    <axis
      xyz="0 0 1" />
    <limit
      lower="-10"
      upper="10"
      effort="100"
      velocity="110" />
  </joint>
  <link
    name="link6">
    <inertial>
      <origin
        xyz="-2.3008E-11 3.2452E-12 -0.0024166"
        rpy="0 0 0" />
      <mass
        value="0.0026503" />
      <inertia
        ixx="3.2947E-07"
        ixy="3.5857E-16"
        ixz="1.0908E-16"
        iyy="3.2947E-07"
        iyz="2.3536E-16"
        izz="6.4653E-07" />
    </inertial>
    <visual>
      <origin
        xyz="0 0 0"
        rpy="0 0 0" />
      <geometry>
        <mesh
          filename="../meshes/link6.STL" />
      </geometry>
      <material
        name="">
        <color
          rgba="1 1 1 1" />
      </material>
    </visual>
    <collision>
      <origin
        xyz="0 0 0"
        rpy="0 0 0" />
      <geometry>
        <mesh
          filename="../meshes/link6.STL" />
      </geometry>
    </collision>
  </link>
  <joint
    name="joint6"
    type="revolute">
    <origin
      xyz="-0.0865 0 -0.002749"
      rpy="3.1416 -1.5708 0" />
    <parent
      link="link5" />
    <child
      link="link6" />
    <axis
      xyz="0 0 1" />
    <limit
      lower="-10"
      upper="10"
      effort="100"
      velocity="110" />
  </joint>
</robot>